<?xml version="1.0" ?>
<!-- Marcheur passif -->
<!-- This file comes from Aldebaran romeo.urdf file with slight modifications:               -->
<!--             - rename joint_base by waist (joint base name in sot is already joint_base) -->
<!--             - waist joint goes from base_link to body (and not base_link)                   -->
<!--             - inverse trunkYaw joint direction (now from body to base_link)                 -->
<!-- Aldebaran file comes from                                                               --> 

<robot name="robot" xmlns:xacro="http://www.ros.org/wiki/xacro">

   <material name="blue">
      <color rgba="0 0 0.8 1"/>
   </material>
   <link name="world"/>

  <joint name="fixed" type="fixed">
    <parent link="world"/>
    <child link="base_link"/>
</joint>
  
  <link name="base_link">
    <inertial>
      <mass value="1.635"/>
      <inertia ixx="86e-03" ixy="-39.84e-6" ixz="3.991e-4" iyy="83e-3" iyz="-38.29e-6" izz="4e-3"/>
      <origin rpy="0 0 -1.57075" xyz="0 0 0.17346"/>
    </inertial>
    
    <visual>
      <geometry>
        <mesh filename="package://yoyoman01_description/meshes/BUSTE.stl" scale="0.001 0.001 0.001"/>
      </geometry>
    <material name="blue"/>
    </visual>
<!--
    <origin rpy="0 0 -1.57075" xyz="0 0 0"/>
-->
    <collision>
      <geometry>
        <mesh filename="package://yoyoman01_description/meshes/BUSTE.stl" scale="0.001 0.001 0.001"/>
      </geometry>
    </collision>
  </link>
  
  <joint name="Neck" type="revolute">
    <parent link="base_link"/>
    <child link="NeckLink"/>
    <origin rpy="0 0 0" xyz="0 0 0.675"/>
    <axis xyz="0 1 0"/>
    <limit effort="0.5" lower="0" upper="0.5" velocity="1"/>
  </joint>
  <link name="NeckLink">
    <inertial>
      <mass value="0.061"/>
      <inertia ixx="2.95e-5" ixy="-7.67e-9" ixz="-3.61e-9" iyy="2.53e-5" iyz="-3.05e-6" izz="1.09e-5"/>
      <origin rpy="0 0 0" xyz="0 0 0.03"/>
    </inertial>
    <visual>
      <geometry>
        <mesh filename="package://yoyoman01_description/meshes/COU.stl" scale="0.001 0.001 0.001"/>
      </geometry>
    <origin rpy="0 0 1.57075" xyz="0 0 0"/>
    </visual>
    <collision>
      <geometry>
        <mesh filename="package://yoyoman01_description/meshes/COU.stl" scale="0.001 0.001 0.001"/>
      </geometry>
    </collision>
  </link>
  
 <joint name="Head" type="revolute">
    <parent link="NeckLink"/>
    <child link="HeadLink"/>
    <origin rpy="0 0 0" xyz="0 0 0.064502"/>
    <axis xyz="0 1 0"/>
    <limit effort="0.5" lower="0" upper="0.5" velocity="1"/>
  </joint>
  <link name="HeadLink">
    <inertial>
      <mass value="0.340"/>
      <inertia ixx="2e-3" ixy="-129.7e-9" ixz="5.391e-5" iyy="3e-3" iyz="-267.9e-9" izz="1e-3"/>
      <origin rpy="0 0 0" xyz="0 0 0.143385"/>
    </inertial>
    <visual>
      <geometry>
        <mesh filename="package://yoyoman01_description/meshes/TETE.stl" scale="0.001 0.001 0.001"/>
      </geometry>
    <origin rpy="0 0 1.57075 " xyz="0 0 0"/>
    <material name="blue"/>
    </visual>
    <collision>
      <geometry>
        <mesh filename="package://yoyoman01_description/meshes/TETE.stl" scale="0.001 0.001 0.001"/>
      </geometry>
    </collision>
  </link>
  

  
<joint name="Rarm" type="revolute">
    <parent link="base_link"/>
    <child link="RArmLink"/>
    <origin rpy="0 0 0" xyz="0 -0.155 0.589901 "/>
    <axis xyz="0 1 0"/>
    <limit effort="5" lower="0" upper="5" velocity="1"/>
  </joint>
<link name="RArmLink">
    <inertial>
      <mass value="0.172"/>
      <inertia ixx="3e-3" ixy="-2.011e-20" ixz="-3.61e-9" iyy="3e-3" iyz="3.05e-6" izz="2.475e-5"/>
      <origin rpy="0 0 0 " xyz="0 0 -0.10032"/>
    </inertial>
    <visual>
      <geometry>
        <mesh filename="package://yoyoman01_description/meshes/BRAS.stl" scale="0.001 0.001 0.001"/>
      </geometry>
    <origin rpy="0 0 -1.57075" xyz="0 0 0"/>
    </visual>
    <collision>
      <geometry>
        <mesh filename="package://yoyoman01_description/meshes/BRAS.stl" scale="0.001 0.001 0.001"/>
      </geometry>
    </collision>
  </link>
  
<joint name="Larm" type="revolute">
    <parent link="base_link"/>
    <child link="LArmLink"/>
    <origin rpy="0 0 0" xyz="0 0.155 0.589901 "/>
    <axis xyz="0 1 0"/>
    <limit effort="2.57" lower="-0.349066" upper="0.279253" velocity="1.9"/>
  </joint>
<link name="LArmLink">
    <inertial>
      <mass value="0.172"/>
      <inertia ixx="3e-3" ixy="2.011e-20" ixz="-3.61e-9" iyy="3e-3" iyz="-3.05e-6" izz="2.475e-5"/>
      <origin rpy="0 0 0 " xyz="0 0 -0.10032"/>
    </inertial>
    <visual>
      <geometry>
        <mesh filename="package://yoyoman01_description/meshes/BRAS.stl" scale="0.001 0.001 0.001"/>
      </geometry>
    <origin rpy="0 0 1.57075" xyz="0 0 0"/>
    </visual>
    <collision>
      <geometry>
        <mesh filename="package://yoyoman01_description/meshes/BRAS.stl" scale="0.001 0.001 0.001"/>
      </geometry>
    </collision>
  </link>
  
  <joint name="RHip" type="revolute">
    <parent link="base_link"/>
    <child link="RHipLink"/>
    <origin rpy="0 0 0" xyz="0 -0.09 0"/>
    <axis xyz="0 1 0"/>
    <limit effort="6" lower="0" upper="6" velocity="1"/>
  </joint>
  <link name="RHipLink">
    <inertial>
      <mass value="0.816"/>
      <inertia ixx="0.001" ixy="1.921e-4" ixz="-0.0001443" iyy="0.002" iyz="1.291e-4" izz="0.002"/>
      <origin rpy="0 0 0" xyz="0.0506 -0.0137 0.0101"/>
    </inertial>
    <visual>
      <geometry>
        <mesh filename="package://yoyoman01_description/meshes/HANCHE_D.stl" scale="0.001 0.001 0.001"/>
      </geometry>
    <origin rpy="0 3.14 1.57075" xyz="0 0 0"/> 
    </visual>
    <collision>
      <geometry>
        <mesh filename="package://yoyoman01_description/meshes/HANCHE_D.stl" scale="0.001 0.001 0.001"/>
      </geometry>
    </collision>
  </link>
  
  <joint name="LHip" type="revolute">
    <parent link="base_link"/>
    <child link="LHipLink"/>
    <origin rpy="0 0 0" xyz="0 0.09 0"/>
    <axis xyz="0 1 0"/>
    <limit effort="6" lower="0" upper="6" velocity="1"/>
  </joint>
  <link name="LHipLink">
    <inertial>
      <mass value="0.816"/>
      <inertia ixx="0.001" ixy="-1.921e-4" ixz="-0.0001443" iyy="0.002" iyz="-1.291e-4" izz="0.002"/>
      <origin rpy="0 0 0" xyz="0.0506 0.0137 0.0101"/>
    </inertial>
    <visual>
      <geometry>
        <mesh filename="package://yoyoman01_description/meshes/HANCHE_G.stl" scale="0.001 0.001 0.001"/>
      </geometry>
    <origin rpy="0 0 1.57075" xyz="0 0 0"/>
    </visual>
    <collision>
      <geometry>
        <mesh filename="package://yoyoman01_description/meshes/HANCHE_G.stl" scale="0.001 0.001 0.001"/>
      </geometry>
    </collision>
  </link>
  
  <joint name="RKnee" type="fixed">
    <parent link="RHipLink"/>
    <child link="RKneeLink"/>
    <origin rpy="0 0 0" xyz="-0.021 -0.068 -0.01"/>
    <axis xyz="0 0 0"/>
    <limit effort="50" lower="0" upper="0.04" velocity="1"/>
  </joint>
  <link name="RKneeLink">
    <inertial>
      <mass value="0.839"/>
      <inertia ixx="80e-3" ixy="17.42e-6" ixz="-154.3e-6" iyy="80e-3" iyz="-3e-3" izz="2e-3"/>
      <origin rpy="0 0 0" xyz="0.01817 -0.01317 -0.557"/>
    </inertial>
    <visual>
      <geometry>
        <mesh filename="package://yoyoman01_description/meshes/JAMBE_G.stl" scale="0.001 0.001 0.001"/>
      </geometry>
    <origin rpy="0 0 3.14" xyz="0 0 0"/>
    <material name="blue"/>
    </visual>
    <collision>
      <geometry>
        <mesh filename="package://yoyoman01_description/meshes/JAMBE_G.stl" scale="0.001 0.001 0.001"/>
      </geometry>
    </collision>
  </link> 
  
  <joint name="LKnee" type="fixed">
    <parent link="LHipLink"/>
    <child link="LKneeLink"/>
    <origin rpy="0 0 0" xyz="-0.021 0.068 -0.01"/>
    <axis xyz="0 0 0"/>
    <limit effort="50" lower="0" upper="0.04" velocity="1"/>
  </joint>
  <link name="LKneeLink">
    <inertial>
      <mass value="0.839"/>
      <inertia ixx="80e-3" ixy="-17.42e-6" ixz="-154.3e-6" iyy="80e-3" iyz="3e-3" izz="2e-3"/>
      <origin rpy="0 0 0" xyz="0.01817 0.01317 -0.557"/>
    </inertial>
    <visual>
      <geometry>
        <mesh filename="package://yoyoman01_description/meshes/JAMBE_D.stl" scale="0.001 0.001 0.001"/>
      </geometry>
    <origin rpy="0 0 3.14" xyz="0 0 0"/>
    <material name="blue"/>
    </visual>
    <collision>
      <geometry>
        <mesh filename="package://yoyoman01_description/meshes/JAMBE_D.stl" scale="0.001 0.001 0.001"/>
      </geometry>
    </collision>
  </link>



<!-- **********Virtual points on the top of the foots ********** -->

  <joint name="RFoot" type="fixed">
    <parent link="RKneeLink"/>
    <child link="RFootLink"/>
    <origin rpy="0 0 0" xyz="-0.0187 0 -0.7775"/>
    <axis xyz="0 0 0"/>
  </joint>
    <link name="RFootLink">
  </link>link>
  
  <joint name="LFoot" type="fixed">
    <parent link="LKneeLink"/>
    <child link="LFootLink"/>
    <origin rpy="0 0 0" xyz="-0.0187 0 -0.7775"/>
    <axis xyz="0 0 0"/>
  </joint>
    <link name="LFootLink">
  </link>link>

<!--
**********Transmissions**********
-->


  <transmission name="tranHead">
    <type>transmission_interface/SimpleTransmission</type>
    <joint name="Head">
      <hardwareInterface>hardware_interface/EffortJointInterface</hardwareInterface>
    </joint>
    <actuator name="motorHead">
      <hardwareInterface>hardware_interface/EffortJointInterface</hardwareInterface>
      <mechanicalReduction>1</mechanicalReduction>
    </actuator>
  </transmission>

  <transmission name="tranNeck">
    <type>transmission_interface/SimpleTransmission</type>
    <joint name="Neck">
      <hardwareInterface>hardware_interface/EffortJointInterface</hardwareInterface>
    </joint>
    <actuator name="motorNeck">
      <hardwareInterface>hardware_interface/EffortJointInterface</hardwareInterface>
      <mechanicalReduction>1</mechanicalReduction>
    </actuator>
  </transmission>

  <transmission name="tranRarm">
    <type>transmission_interface/SimpleTransmission</type>
    <joint name="Rarm">
      <hardwareInterface>hardware_interface/EffortJointInterface</hardwareInterface>
    </joint>
    <actuator name="motorRarm">
      <hardwareInterface>hardware_interface/EffortJointInterface</hardwareInterface>
      <mechanicalReduction>1</mechanicalReduction>
    </actuator>
  </transmission>

  <transmission name="tranLarm">
    <type>transmission_interface/SimpleTransmission</type>
    <joint name="Larm">
      <hardwareInterface>hardware_interface/EffortJointInterface</hardwareInterface>
    </joint>
    <actuator name="motorLarm">
      <hardwareInterface>hardware_interface/EffortJointInterface</hardwareInterface>
      <mechanicalReduction>1</mechanicalReduction>
    </actuator>
  </transmission>

  <transmission name="tranRHip">
    <type>transmission_interface/SimpleTransmission</type>
    <joint name="RHip">
      <hardwareInterface>hardware_interface/EffortJointInterface</hardwareInterface>
    </joint>
    <actuator name="motorRHip">
      <hardwareInterface>hardware_interface/EffortJointInterface</hardwareInterface>
      <mechanicalReduction>1</mechanicalReduction>
    </actuator>
  </transmission>

  <transmission name="tranLHip">
    <type>transmission_interface/SimpleTransmission</type>
    <joint name="LHip">
      <hardwareInterface>hardware_interface/EffortJointInterface</hardwareInterface>
    </joint>
    <actuator name="motorLHip">
      <hardwareInterface>hardware_interface/EffortJointInterface</hardwareInterface>
      <mechanicalReduction>1</mechanicalReduction>
    </actuator>
  </transmission>
  <gazebo>
    <plugin name="gazebo_ros_control" filename="libgazebo_ros_control.so">
      <robotNamespace>/yoyoman01</robotNamespace>
    </plugin>
  </gazebo>
</robot>


 



